Workbook

Sheet Sheet1
B2: Party Name | C2: Place | D2: Phone No. | E2: Email Id | F2: Fax No.
B4: LOYAL TEXTILE MILLS LTD | C4: KOVILPATTI. | D4: - | E4: - | F4: -
B5: R.V.S. SPINNERS | C5: IDAISEVAL | D5: - | E5: - | F5: -
B6: SRI SRINIVASA TRADER | C6: -- | D6: - | E6: - | F6: -
B7: SRI ARJUNA TRADERS | C7: RAJAPALAYAM | D7: - | E7: - | F7: -
B8: ESWARAN | C8: TAMILNADU | D8: - | E8: - | F8: -
B9: LOYAL TEXTILE MILLS LTD-UNIT II | C9: SIVAGANGAI | D9: - | E9: - | F9: -
B10: VISHNU TRADING COMPANY | C10: MADURAI | D10: - | E10: - | F10: -
B11: SHREE ANGALAPARAMESWARI SPINNING MILLS | C11: COIMBATORE | D11: - | E11: - | F11: -
B12: SUPER TRADERS | C12: MADURAI | D12: - | E12: - | F12: -
B13: K.KUMAR | C13: KOVILPATTI | D13: - | E13: - | F13: -
B14: KUMAR | C14: KOVILPATTI | D14: - | E14: - | F14: -
... B125: WELCOME WILLOWS | C125: RAJAPALAYAM | D125: - | E125: - | F125: -
B126: PAVANASUTHA CORPORATION | C126: SIDDHIPET | D126: 0 | E126: 0 | F126: 0
B127: BALAJI COTEX INDIA PVT LTD | C127: HANAMKONDA | D127: - | E127: - | F127: -
B128: VAIBHAV COTTON CORPORATION | C128: KARIMNAGAR | D128: 253654 | E128: vaibhavcc2009@yahoo.com | F128: -
B129: VINCOT AGENCIES | C129: KHANDWA | D129: 04563-221616 | E129: - | F129: 04563-225000
B130: J.R.TEXTILES | C130: HINGANGHAT | D130: 07513-244043 | E130: jrbaidgroup@yahoo.co.in | F130: -
B131: SHRI BALAJI FIBERS | C131: YAVATMAL | D131: - | E131: balajicul@gmail.com | F131: -
B132: INDIRA COTTON PROCESSOR WANI | C132: YAVATMAL | D132: - | E132: icp_wani@yahoo.in | F132: -
B133: MANISH COTTON & FIBERS | C133: AKOLA | D133: 230702 | E133: - | F133: 08732-236492
B134: SREE MANJUNATHA COTTON MILLS | C134: SHAHAPUR | D134: 08479-240505 | E134: - | F134: -
B135: RUKHMANI COTTEX | C135: HINGANGHAT | D135: 244175 | E135: - | F135: -
B136: SHIVAJI IMPEX | C136: NAGPUR | D136: - | E136: - | F136: -
B137: SHIVAJI CMS | C137: AKKJUN | D137: - | E137: - | F137: -
B138: R.K.FIBER | C138: WANI | D138: - | E138: - | F138: -
B139: LAKSHMI COTTON CORPORATION | C139: VADAKKUPATTI | D139: - | E139: - | F139: -
B140: NEW TAMIL NADU ROADWAYS | C140: AURANGABAD | D140: - | E140: - | F140: -
B141: PALLAVI LORRY SUPPLY OFFICE | C141: ADILABAD | D141: - | E141: - | F141: -
B142: BHAVANI ENTERPRISES | C142: WARANGAL | D142: - | E142: - | F142: -
B143: MADHU LORRY SERVICES | C143: MADURANAGAR | D143: - | E143: - | F143: -
B144: KAVERI GINNING INDUSTRIES PVT LTD | C144: NALGONDA | D144: - | E144: - | F144: -
B145: SRI KAMATCHI AGRO SERVICE | C145: VALHAIYUR | D145: - | E145: - | F145: -
B146: FELIX TRADERS | C146: KALLAKUDI | D146: - | E146: - | F146: -
B147: TAMILNADU KERALA ROADWAYS | C147: YAVATMAL | D147: - | E147: - | F147: -
... B190: SATPAL ROAD LINES & CO | C190: NAGPUR | D190: - | E190: - | F190: -
B191: ALL INDIA GOODS SERVICE | C191: YAVATMAL | D191: 7232244317 | E191: aigs17@yahoo.in | F191: -
B192: MAHALAXMI TRANSPORT | C192: BHATKHEDI | D192: - | E192: - | F192: -
B193: ELKAY COTTON PVT. LTD. | C193: RATLAM | D193: - | E193: - | F193: -
B194: PRAKASH FATS & PROTEINS (INDIA) | C194: HINGANGHAT | D194: - | E194: - | F194: -
...

Sheet Sheet2
A1: Code | B1: Account Name
A2: 1 | B2: SHRI BALAJI FIBRES | C2: =IF(COUNTIF(Sheet1!$B:$B,B2)>0,"Present","Not Present") -> Not Present | E2: =IFERROR(IF(VLOOKUP(B2,Sheet1!$B:$B,1,FALSE)=B2,"Present"),"Not Present") -> Not Present
A3: 2 | B3: SUBBURAAJ COTTON MILL PVT. LTD. | C3: =IF(COUNTIF(Sheet1!$B:$B,B3)>0,"Present","Not Present") -> Not Present | E3: =IFERROR(IF(VLOOKUP(B3,Sheet1!$B:$B,1,FALSE)=B3,"Present"),"Not Present") -> Not Present
A4: 3 | B4: SRI VINAYAKA INDUSTRIES | C4: =IF(COUNTIF(Sheet1!$B:$B,B4)>0,"Present","Not Present") -> Not Present | E4: =IFERROR(IF(VLOOKUP(B4,Sheet1!$B:$B,1,FALSE)=B4,"Present"),"Not Present") -> Not Present
A5: 4 | B5: SANGAMESHWAR INDUSTRIES | C5: =IF(COUNTIF(Sheet1!$B:$B,B5)>0,"Present","Not Present") -> Not Present | E5: =IFERROR(IF(VLOOKUP(B5,Sheet1!$B:$B,1,FALSE)=B5,"Present"),"Not Present") -> Not Present
A6: 5 | B6: DEEPALI EXPORTS | C6: =IF(COUNTIF(Sheet1!$B:$B,B6)>0,"Present","Not Present") -> Not Present | E6: =IFERROR(IF(VLOOKUP(B6,Sheet1!$B:$B,1,FALSE)=B6,"Present"),"Not Present") -> Not Present
A7: 6 | B7: M/S SANGAM INDUSTRIES | C7: =IF(COUNTIF(Sheet1!$B:$B,B7)>0,"Present","Not Present") -> Not Present | E7: =IFERROR(IF(VLOOKUP(B7,Sheet1!$B:$B,1,FALSE)=B7,"Present"),"Not Present") -> Not Present
A8: 7 | B8: KUSHAL FIBERS | C8: =IF(COUNTIF(Sheet1!$B:$B,B8)>0,"Present","Not Present") -> Not Present | E8: =IFERROR(IF(VLOOKUP(B8,Sheet1!$B:$B,1,FALSE)=B8,"Present"),"Not Present") -> Not Present
A9: 8 | B9: LAXMINARAYAN COTTON COMPANY | C9: =IF(COUNTIF(Sheet1!$B:$B,B9)>0,"Present","Not Present") -> Not Present | E9: =IFERROR(IF(VLOOKUP(B9,Sheet1!$B:$B,1,FALSE)=B9,"Present"),"Not Present") -> Not Present
A10: 9 | B10: M/S. SIDDHARTH GINNING & PRESSING FACTORY | C10: =IF(COUNTIF(Sheet1!$B:$B,B10)>0,"Present","Not Present") -> Not Present | E10: =IFERROR(IF(VLOOKUP(B10,Sheet1!$B:$B,1,FALSE)=B10,"Present"),"Not Present") -> Not Present
A11: 10 | B11: NAVIN COTEX | C11: =IF(COUNTIF(Sheet1!$B:$B,B11)>0,"Present","Not Present") -> Not Present | E11: =IFERROR(IF(VLOOKUP(B11,Sheet1!$B:$B,1,FALSE)=B11,"Present"),"Not Present") -> Not Present
A12: 11 | B12: KAVERI GINNING MILLS PVT LTD | C12: =IF(COUNTIF(Sheet1!$B:$B,B12)>0,"Present","Not Present") -> Not Present | E12: =IFERROR(IF(VLOOKUP(B12,Sheet1!$B:$B,1,FALSE)=B12,"Present"),"Not Present") -> Not Present
A13: 12 | B13: PAWAN COTTON INDUSTRIES | C13: =IF(COUNTIF(Sheet1!$B:$B,B13)>0,"Present","Not Present") -> Not Present | E13: =IFERROR(IF(VLOOKUP(B13,Sheet1!$B:$B,1,FALSE)=B13,"Present"),"Not Present") -> Not Present
... A33: 32 | B33: SULTANIA OIL INDUSTRIES P LTD | C33: =IF(COUNTIF(Sheet1!$B:$B,B33)>0,"Present","Not Present") -> Not Present | E33: =IFERROR(IF(VLOOKUP(B33,Sheet1!$B:$B,1,FALSE)=B33,"Present"),"Not Present") -> Not Present
C34: =COUNTIF(C2:C33,"Present") -> 0
